Unhandled exception
Traceback (most recent call last):
  File "./app/tasks.py", line 194, in bg_add_article
    content = epubConverted(path, u)
  File "./app/main/ebooks.py", line 17, in epubConverted
    book = epub.read_epub(filepath)
  File "/Users/rr/Desktop/RR/code/LearnBetter/venv/lib/python3.6/site-packages/ebooklib/epub.py", line 1739, in read_epub
    book = reader.load()
  File "/Users/rr/Desktop/RR/code/LearnBetter/venv/lib/python3.6/site-packages/ebooklib/epub.py", line 1397, in load
    self._load()
  File "/Users/rr/Desktop/RR/code/LearnBetter/venv/lib/python3.6/site-packages/ebooklib/epub.py", line 1686, in _load
    self.zf = zipfile.ZipFile(self.file_name, 'r', compression=zipfile.ZIP_DEFLATED, allowZip64=True)
  File "/Library/Frameworks/Python.framework/Versions/3.6/lib/python3.6/zipfile.py", line 1090, in __init__
    self.fp = io.open(file, filemode)
FileNotFoundError: [Errno 2] No such file or directory: '/Users/rr/Desktop/RR/code/LearnBetter/app/temp/586df63c-959b-4947-b02b-5b4990903b05.epub'
Learning tool startup
Learning tool startup
Learning tool startup
Unhandled exception
Traceback (most recent call last):
  File "./app/tasks.py", line 194, in bg_add_article
    content = epubConverted(path, u)
  File "./app/main/ebooks.py", line 17, in epubConverted
    book = epub.read_epub(filepath)
  File "/Users/rr/Desktop/RR/code/LearnBetter/venv/lib/python3.6/site-packages/ebooklib/epub.py", line 1739, in read_epub
    book = reader.load()
  File "/Users/rr/Desktop/RR/code/LearnBetter/venv/lib/python3.6/site-packages/ebooklib/epub.py", line 1397, in load
    self._load()
  File "/Users/rr/Desktop/RR/code/LearnBetter/venv/lib/python3.6/site-packages/ebooklib/epub.py", line 1686, in _load
    self.zf = zipfile.ZipFile(self.file_name, 'r', compression=zipfile.ZIP_DEFLATED, allowZip64=True)
  File "/Library/Frameworks/Python.framework/Versions/3.6/lib/python3.6/zipfile.py", line 1090, in __init__
    self.fp = io.open(file, filemode)
FileNotFoundError: [Errno 2] No such file or directory: '/Users/rr/Desktop/RR/code/LearnBetter/app/temp/49869f05-eb7a-4652-af33-519d7d1fcdbd.epub'
Unhandled exception
Traceback (most recent call last):
  File "./app/tasks.py", line 194, in bg_add_article
    content = epubConverted(path, u)
  File "./app/main/ebooks.py", line 17, in epubConverted
    book = epub.read_epub(filepath)
  File "/Users/rr/Desktop/RR/code/LearnBetter/venv/lib/python3.6/site-packages/ebooklib/epub.py", line 1739, in read_epub
    book = reader.load()
  File "/Users/rr/Desktop/RR/code/LearnBetter/venv/lib/python3.6/site-packages/ebooklib/epub.py", line 1397, in load
    self._load()
  File "/Users/rr/Desktop/RR/code/LearnBetter/venv/lib/python3.6/site-packages/ebooklib/epub.py", line 1686, in _load
    self.zf = zipfile.ZipFile(self.file_name, 'r', compression=zipfile.ZIP_DEFLATED, allowZip64=True)
  File "/Library/Frameworks/Python.framework/Versions/3.6/lib/python3.6/zipfile.py", line 1090, in __init__
    self.fp = io.open(file, filemode)
FileNotFoundError: [Errno 2] No such file or directory: '/Users/rr/Desktop/RR/code/LearnBetter/app/temp/49869f05-eb7a-4652-af33-519d7d1fcdbd.epub'
Learning tool startup
Learning tool startup
Learning tool startup
Unhandled exception
Traceback (most recent call last):
  File "./app/tasks.py", line 194, in bg_add_article
    content = epubConverted(path, u)
  File "./app/main/ebooks.py", line 17, in epubConverted
    book = epub.read_epub(filepath)
  File "/Users/rr/Desktop/RR/code/LearnBetter/venv/lib/python3.6/site-packages/ebooklib/epub.py", line 1739, in read_epub
    book = reader.load()
  File "/Users/rr/Desktop/RR/code/LearnBetter/venv/lib/python3.6/site-packages/ebooklib/epub.py", line 1397, in load
    self._load()
  File "/Users/rr/Desktop/RR/code/LearnBetter/venv/lib/python3.6/site-packages/ebooklib/epub.py", line 1686, in _load
    self.zf = zipfile.ZipFile(self.file_name, 'r', compression=zipfile.ZIP_DEFLATED, allowZip64=True)
  File "/Library/Frameworks/Python.framework/Versions/3.6/lib/python3.6/zipfile.py", line 1090, in __init__
    self.fp = io.open(file, filemode)
FileNotFoundError: [Errno 2] No such file or directory: '/Users/rr/Desktop/RR/code/LearnBetter/app/temp/ceee1069-638b-4fde-838d-fd9d692c35a4.epub'
Unhandled exception
Traceback (most recent call last):
  File "./app/tasks.py", line 194, in bg_add_article
    content = epubConverted(path, u)
  File "./app/main/ebooks.py", line 17, in epubConverted
    book = epub.read_epub(filepath)
  File "/Users/rr/Desktop/RR/code/LearnBetter/venv/lib/python3.6/site-packages/ebooklib/epub.py", line 1739, in read_epub
    book = reader.load()
  File "/Users/rr/Desktop/RR/code/LearnBetter/venv/lib/python3.6/site-packages/ebooklib/epub.py", line 1397, in load
    self._load()
  File "/Users/rr/Desktop/RR/code/LearnBetter/venv/lib/python3.6/site-packages/ebooklib/epub.py", line 1686, in _load
    self.zf = zipfile.ZipFile(self.file_name, 'r', compression=zipfile.ZIP_DEFLATED, allowZip64=True)
  File "/Library/Frameworks/Python.framework/Versions/3.6/lib/python3.6/zipfile.py", line 1090, in __init__
    self.fp = io.open(file, filemode)
FileNotFoundError: [Errno 2] No such file or directory: '/Users/rr/Desktop/RR/code/LearnBetter/app/temp/ceee1069-638b-4fde-838d-fd9d692c35a4.epub'
Learning tool startup
Learning tool startup
Learning tool startup
Learning tool startup
Learning tool startup
Learning tool startup
Learning tool startup
Learning tool startup
Learning tool startup
Learning tool startup
Learning tool startup
Learning tool startup
Learning tool startup
Learning tool startup
Learning tool startup
Learning tool startup
Learning tool startup
Learning tool startup
Learning tool startup
Learning tool startup
Learning tool startup
Learning tool startup
Learning tool startup
Learning tool startup
Learning tool startup
Learning tool startup
Learning tool startup
Unhandled exception
Traceback (most recent call last):
  File "./app/tasks.py", line 235, in set_images_lazy
    _set_task_progress(0)
  File "./app/tasks.py", line 28, in _set_task_progress
    task.user.add_notification('task_progress',
AttributeError: 'NoneType' object has no attribute 'user'
Unhandled exception
Traceback (most recent call last):
  File "./app/tasks.py", line 235, in set_images_lazy
    _set_task_progress(0)
  File "./app/tasks.py", line 28, in _set_task_progress
    task.user.add_notification('task_progress',
AttributeError: 'NoneType' object has no attribute 'user'
Learning tool startup
Learning tool startup
Learning tool startup
Learning tool startup
Learning tool startup
Learning tool startup
Learning tool startup
Learning tool startup
Learning tool startup
Unhandled exception
Traceback (most recent call last):
  File "./app/tasks.py", line 238, in set_images_lazy
    soup = BeautifulSoup(a.content, "html5lib")
AttributeError: 'NoneType' object has no attribute 'content'
Unhandled exception
Traceback (most recent call last):
  File "./app/tasks.py", line 238, in set_images_lazy
    soup = BeautifulSoup(a.content, "html5lib")
AttributeError: 'NoneType' object has no attribute 'content'
Learning tool startup
Learning tool startup
Learning tool startup
Unhandled exception
Traceback (most recent call last):
  File "./app/tasks.py", line 235, in set_images_lazy
    _set_task_progress(0)
  File "./app/tasks.py", line 28, in _set_task_progress
    task.user.add_notification('task_progress',
AttributeError: 'NoneType' object has no attribute 'user'
Unhandled exception
Traceback (most recent call last):
  File "./app/tasks.py", line 235, in set_images_lazy
    _set_task_progress(0)
  File "./app/tasks.py", line 28, in _set_task_progress
    task.user.add_notification('task_progress',
AttributeError: 'NoneType' object has no attribute 'user'
Learning tool startup
Learning tool startup
Learning tool startup
Unhandled exception
Traceback (most recent call last):
  File "./app/tasks.py", line 237, in set_images_lazy
    a = Article.query.get(a.id)
  File "/Users/rr/Desktop/RR/code/LearnBetter/venv/lib/python3.6/site-packages/sqlalchemy/orm/attributes.py", line 287, in __get__
    return self.impl.get(instance_state(instance), dict_)
  File "/Users/rr/Desktop/RR/code/LearnBetter/venv/lib/python3.6/site-packages/sqlalchemy/orm/attributes.py", line 718, in get
    value = state._load_expired(state, passive)
  File "/Users/rr/Desktop/RR/code/LearnBetter/venv/lib/python3.6/site-packages/sqlalchemy/orm/state.py", line 652, in _load_expired
    self.manager.deferred_scalar_loader(self, toload)
  File "/Users/rr/Desktop/RR/code/LearnBetter/venv/lib/python3.6/site-packages/sqlalchemy/orm/loading.py", line 946, in load_scalar_attributes
    "attribute refresh operation cannot proceed" % (state_str(state))
sqlalchemy.orm.exc.DetachedInstanceError: Instance <Article at 0x104cc9cf8> is not bound to a Session; attribute refresh operation cannot proceed (Background on this error at: http://sqlalche.me/e/bhk3)
Unhandled exception
Traceback (most recent call last):
  File "./app/tasks.py", line 237, in set_images_lazy
    a = Article.query.get(a.id)
  File "/Users/rr/Desktop/RR/code/LearnBetter/venv/lib/python3.6/site-packages/sqlalchemy/orm/attributes.py", line 287, in __get__
    return self.impl.get(instance_state(instance), dict_)
  File "/Users/rr/Desktop/RR/code/LearnBetter/venv/lib/python3.6/site-packages/sqlalchemy/orm/attributes.py", line 718, in get
    value = state._load_expired(state, passive)
  File "/Users/rr/Desktop/RR/code/LearnBetter/venv/lib/python3.6/site-packages/sqlalchemy/orm/state.py", line 652, in _load_expired
    self.manager.deferred_scalar_loader(self, toload)
  File "/Users/rr/Desktop/RR/code/LearnBetter/venv/lib/python3.6/site-packages/sqlalchemy/orm/loading.py", line 946, in load_scalar_attributes
    "attribute refresh operation cannot proceed" % (state_str(state))
sqlalchemy.orm.exc.DetachedInstanceError: Instance <Article at 0x104cc9cf8> is not bound to a Session; attribute refresh operation cannot proceed (Background on this error at: http://sqlalche.me/e/bhk3)
Learning tool startup
Learning tool startup
Learning tool startup
