Learning tool startup
Learning tool startup
Learning tool startup
Unhandled exception
Traceback (most recent call last):
  File "./app/tasks.py", line 110, in export_highlights
    data.append({'text': str(highlight.text, 'utf-8'),
TypeError: decoding str is not supported
Unhandled exception
Traceback (most recent call last):
  File "./app/tasks.py", line 110, in export_highlights
    data.append({'text': str(highlight.text, 'utf-8'),
TypeError: decoding str is not supported
Learning tool startup
Learning tool startup
Learning tool startup
Learning tool startup
Learning tool startup
Learning tool startup
Learning tool startup
Learning tool startup
Learning tool startup
Learning tool startup
Learning tool startup
Learning tool startup
Unhandled exception
Traceback (most recent call last):
  File "./app/tasks.py", line 110, in export_highlights
    data.append({'text': str(highlight.text.encode('windows-1252'), 'utf-8'),
UnicodeDecodeError: 'utf-8' codec can't decode byte 0x92 in position 65: invalid start byte
Unhandled exception
Traceback (most recent call last):
  File "./app/tasks.py", line 110, in export_highlights
    data.append({'text': str(highlight.text.encode('windows-1252'), 'utf-8'),
UnicodeDecodeError: 'utf-8' codec can't decode byte 0x92 in position 65: invalid start byte
Learning tool startup
Learning tool startup
Learning tool startup
Learning tool startup
Learning tool startup
Learning tool startup
Learning tool startup
Learning tool startup
Learning tool startup
Learning tool startup
Learning tool startup
Learning tool startup
Learning tool startup
Learning tool startup
Learning tool startup
Learning tool startup
Learning tool startup
Learning tool startup
Learning tool startup
Learning tool startup
Learning tool startup
Learning tool startup
Learning tool startup
Learning tool startup
Learning tool startup
Learning tool startup
Learning tool startup
Learning tool startup
Learning tool startup
Learning tool startup
Unhandled exception
Traceback (most recent call last):
  File "./app/tasks.py", line 104, in export_highlights
    'from': highlight.article.title.decode(),
AttributeError: 'str' object has no attribute 'decode'
Unhandled exception
Traceback (most recent call last):
  File "./app/tasks.py", line 104, in export_highlights
    'from': highlight.article.title.decode(),
AttributeError: 'str' object has no attribute 'decode'
Learning tool startup
Learning tool startup
Learning tool startup
Unhandled exception
Traceback (most recent call last):
  File "./app/tasks.py", line 118, in export_highlights
    with open(f'{path}/highlights.json', 'w', encoding='utf-16') as f:
UnboundLocalError: local variable 'path' referenced before assignment
Unhandled exception
Traceback (most recent call last):
  File "./app/tasks.py", line 118, in export_highlights
    with open(f'{path}/highlights.json', 'w', encoding='utf-16') as f:
UnboundLocalError: local variable 'path' referenced before assignment
Learning tool startup
Learning tool startup
Learning tool startup
Learning tool startup
Learning tool startup
Learning tool startup
Learning tool startup
Learning tool startup
Learning tool startup
Learning tool startup
Learning tool startup
Learning tool startup
Learning tool startup
Learning tool startup
Learning tool startup
Unhandled exception
Traceback (most recent call last):
  File "./app/tasks.py", line 125, in export_highlights
    attachments=[('highlights.json', 'text/json', f.read())],
io.UnsupportedOperation: not readable
Unhandled exception
Traceback (most recent call last):
  File "./app/tasks.py", line 125, in export_highlights
    attachments=[('highlights.json', 'text/json', f.read())],
io.UnsupportedOperation: not readable
Learning tool startup
Learning tool startup
Learning tool startup
Learning tool startup
Learning tool startup
Learning tool startup
Learning tool startup
Learning tool startup
Learning tool startup
Learning tool startup
Learning tool startup
Learning tool startup
Unhandled exception
Traceback (most recent call last):
  File "./app/tasks.py", line 123, in export_highlights
    j.write(f.read(encoding='utf-16'))
TypeError: read() takes no keyword arguments
Unhandled exception
Traceback (most recent call last):
  File "./app/tasks.py", line 123, in export_highlights
    j.write(f.read(encoding='utf-16'))
TypeError: read() takes no keyword arguments
Learning tool startup
Learning tool startup
Learning tool startup
Learning tool startup
Learning tool startup
Learning tool startup
Learning tool startup
Learning tool startup
Learning tool startup
Unhandled exception
Traceback (most recent call last):
  File "./app/tasks.py", line 43, in export_highlights
    az_path_base = f'{current_user.id}/exports/'
NameError: name 'current_user' is not defined
Unhandled exception
Traceback (most recent call last):
  File "./app/tasks.py", line 43, in export_highlights
    az_path_base = f'{current_user.id}/exports/'
NameError: name 'current_user' is not defined
Learning tool startup
Learning tool startup
Learning tool startup
Unhandled exception
Traceback (most recent call last):
  File "./app/tasks.py", line 43, in export_highlights
    az_path_base = f'{current_user.id}/exports/'
NameError: name 'current_user' is not defined
Unhandled exception
Traceback (most recent call last):
  File "./app/tasks.py", line 43, in export_highlights
    az_path_base = f'{current_user.id}/exports/'
NameError: name 'current_user' is not defined
Learning tool startup
Learning tool startup
Learning tool startup
Learning tool startup
Learning tool startup
Learning tool startup
Learning tool startup
Learning tool startup
Learning tool startup
Learning tool startup
Learning tool startup
Learning tool startup
Learning tool startup
Learning tool startup
Learning tool startup
Learning tool startup
Learning tool startup
Learning tool startup
Learning tool startup
Learning tool startup
Learning tool startup
Learning tool startup
Learning tool startup
Learning tool startup
Learning tool startup
Learning tool startup
Learning tool startup
Learning tool startup
Learning tool startup
Learning tool startup
Learning tool startup
Learning tool startup
Learning tool startup
Learning tool startup
Learning tool startup
Learning tool startup
Learning tool startup
Learning tool startup
Learning tool startup
Learning tool startup
Learning tool startup
Learning tool startup
Learning tool startup
Learning tool startup
Learning tool startup
Unhandled exception
Traceback (most recent call last):
  File "./app/tasks.py", line 148, in bg_add_article
    _set_task_progress(0)
  File "./app/tasks.py", line 26, in _set_task_progress
    task.user.add_notification('task_progress',
AttributeError: 'NoneType' object has no attribute 'user'
Unhandled exception
Traceback (most recent call last):
  File "./app/tasks.py", line 148, in bg_add_article
    _set_task_progress(0)
  File "./app/tasks.py", line 26, in _set_task_progress
    task.user.add_notification('task_progress',
AttributeError: 'NoneType' object has no attribute 'user'
Learning tool startup
Learning tool startup
Learning tool startup
Unhandled exception
Traceback (most recent call last):
  File "./app/tasks.py", line 154, in bg_add_article
    pdf = importPDF(path)
  File "./app/main/pdf.py", line 67, in importPDF
    az_path_base = f'{current_user.id}/{title_for_dir}/'
  File "/Users/rr/Desktop/RR/code/LearnBetter/venv/lib/python3.6/site-packages/werkzeug/local.py", line 347, in __getattr__
    return getattr(self._get_current_object(), name)
AttributeError: 'NoneType' object has no attribute 'id'
Unhandled exception
Traceback (most recent call last):
  File "./app/tasks.py", line 154, in bg_add_article
    pdf = importPDF(path)
  File "./app/main/pdf.py", line 67, in importPDF
    az_path_base = f'{current_user.id}/{title_for_dir}/'
  File "/Users/rr/Desktop/RR/code/LearnBetter/venv/lib/python3.6/site-packages/werkzeug/local.py", line 347, in __getattr__
    return getattr(self._get_current_object(), name)
AttributeError: 'NoneType' object has no attribute 'id'
Learning tool startup
Learning tool startup
Learning tool startup
Learning tool startup
Learning tool startup
Learning tool startup
Learning tool startup
Learning tool startup
Learning tool startup
Learning tool startup
Learning tool startup
Learning tool startup
Learning tool startup
Learning tool startup
Learning tool startup
Learning tool startup
Learning tool startup
Learning tool startup
Learning tool startup
Learning tool startup
Learning tool startup
Learning tool startup
Learning tool startup
Learning tool startup
Learning tool startup
Learning tool startup
Learning tool startup
Learning tool startup
Learning tool startup
Learning tool startup
Learning tool startup
Learning tool startup
Learning tool startup
Learning tool startup
Learning tool startup
Learning tool startup
Learning tool startup
Learning tool startup
Learning tool startup
Unhandled exception
Traceback (most recent call last):
  File "./app/tasks.py", line 194, in bg_add_article
    content = epubConverted(path, u)
  File "./app/main/ebooks.py", line 17, in epubConverted
    book = epub.read_epub(filepath)
  File "/Users/rr/Desktop/RR/code/LearnBetter/venv/lib/python3.6/site-packages/ebooklib/epub.py", line 1739, in read_epub
    book = reader.load()
  File "/Users/rr/Desktop/RR/code/LearnBetter/venv/lib/python3.6/site-packages/ebooklib/epub.py", line 1397, in load
    self._load()
  File "/Users/rr/Desktop/RR/code/LearnBetter/venv/lib/python3.6/site-packages/ebooklib/epub.py", line 1686, in _load
    self.zf = zipfile.ZipFile(self.file_name, 'r', compression=zipfile.ZIP_DEFLATED, allowZip64=True)
  File "/Library/Frameworks/Python.framework/Versions/3.6/lib/python3.6/zipfile.py", line 1090, in __init__
    self.fp = io.open(file, filemode)
FileNotFoundError: [Errno 2] No such file or directory: '/Users/rr/Desktop/RR/code/LearnBetter/app/temp/586df63c-959b-4947-b02b-5b4990903b05.epub'
