Exception on /register [POST]
Traceback (most recent call last):
  File "/Users/rr/Desktop/code/LearnBetter/venv/lib/python3.7/site-packages/sqlalchemy/engine/base.py", line 1284, in _execute_context
    cursor, statement, parameters, context
  File "/Users/rr/Desktop/code/LearnBetter/venv/lib/python3.7/site-packages/sqlalchemy/engine/default.py", line 590, in do_execute
    cursor.execute(statement, parameters)
sqlite3.IntegrityError: UNIQUE constraint failed: user.username

The above exception was the direct cause of the following exception:

Traceback (most recent call last):
  File "/Users/rr/Desktop/code/LearnBetter/venv/lib/python3.7/site-packages/flask/app.py", line 2447, in wsgi_app
    response = self.full_dispatch_request()
  File "/Users/rr/Desktop/code/LearnBetter/venv/lib/python3.7/site-packages/flask/app.py", line 1952, in full_dispatch_request
    rv = self.handle_user_exception(e)
  File "/Users/rr/Desktop/code/LearnBetter/venv/lib/python3.7/site-packages/flask/app.py", line 1821, in handle_user_exception
    reraise(exc_type, exc_value, tb)
  File "/Users/rr/Desktop/code/LearnBetter/venv/lib/python3.7/site-packages/flask/_compat.py", line 39, in reraise
    raise value
  File "/Users/rr/Desktop/code/LearnBetter/venv/lib/python3.7/site-packages/flask/app.py", line 1950, in full_dispatch_request
    rv = self.dispatch_request()
  File "/Users/rr/Desktop/code/LearnBetter/venv/lib/python3.7/site-packages/flask/app.py", line 1936, in dispatch_request
    return self.view_functions[rule.endpoint](**req.view_args)
  File "/Users/rr/Desktop/code/LearnBetter/app/routes.py", line 168, in register
    db.session.commit()
  File "/Users/rr/Desktop/code/LearnBetter/venv/lib/python3.7/site-packages/sqlalchemy/orm/scoping.py", line 163, in do
    return getattr(self.registry(), name)(*args, **kwargs)
  File "/Users/rr/Desktop/code/LearnBetter/venv/lib/python3.7/site-packages/sqlalchemy/orm/session.py", line 1042, in commit
    self.transaction.commit()
  File "/Users/rr/Desktop/code/LearnBetter/venv/lib/python3.7/site-packages/sqlalchemy/orm/session.py", line 504, in commit
    self._prepare_impl()
  File "/Users/rr/Desktop/code/LearnBetter/venv/lib/python3.7/site-packages/sqlalchemy/orm/session.py", line 483, in _prepare_impl
    self.session.flush()
  File "/Users/rr/Desktop/code/LearnBetter/venv/lib/python3.7/site-packages/sqlalchemy/orm/session.py", line 2523, in flush
    self._flush(objects)
  File "/Users/rr/Desktop/code/LearnBetter/venv/lib/python3.7/site-packages/sqlalchemy/orm/session.py", line 2664, in _flush
    transaction.rollback(_capture_exception=True)
  File "/Users/rr/Desktop/code/LearnBetter/venv/lib/python3.7/site-packages/sqlalchemy/util/langhelpers.py", line 69, in __exit__
    exc_value, with_traceback=exc_tb,
  File "/Users/rr/Desktop/code/LearnBetter/venv/lib/python3.7/site-packages/sqlalchemy/util/compat.py", line 178, in raise_
    raise exception
  File "/Users/rr/Desktop/code/LearnBetter/venv/lib/python3.7/site-packages/sqlalchemy/orm/session.py", line 2624, in _flush
    flush_context.execute()
  File "/Users/rr/Desktop/code/LearnBetter/venv/lib/python3.7/site-packages/sqlalchemy/orm/unitofwork.py", line 422, in execute
    rec.execute(self)
  File "/Users/rr/Desktop/code/LearnBetter/venv/lib/python3.7/site-packages/sqlalchemy/orm/unitofwork.py", line 589, in execute
    uow,
  File "/Users/rr/Desktop/code/LearnBetter/venv/lib/python3.7/site-packages/sqlalchemy/orm/persistence.py", line 245, in save_obj
    insert,
  File "/Users/rr/Desktop/code/LearnBetter/venv/lib/python3.7/site-packages/sqlalchemy/orm/persistence.py", line 1136, in _emit_insert_statements
    statement, params
  File "/Users/rr/Desktop/code/LearnBetter/venv/lib/python3.7/site-packages/sqlalchemy/engine/base.py", line 1020, in execute
    return meth(self, multiparams, params)
  File "/Users/rr/Desktop/code/LearnBetter/venv/lib/python3.7/site-packages/sqlalchemy/sql/elements.py", line 298, in _execute_on_connection
    return connection._execute_clauseelement(self, multiparams, params)
  File "/Users/rr/Desktop/code/LearnBetter/venv/lib/python3.7/site-packages/sqlalchemy/engine/base.py", line 1139, in _execute_clauseelement
    distilled_params,
  File "/Users/rr/Desktop/code/LearnBetter/venv/lib/python3.7/site-packages/sqlalchemy/engine/base.py", line 1324, in _execute_context
    e, statement, parameters, cursor, context
  File "/Users/rr/Desktop/code/LearnBetter/venv/lib/python3.7/site-packages/sqlalchemy/engine/base.py", line 1518, in _handle_dbapi_exception
    sqlalchemy_exception, with_traceback=exc_info[2], from_=e
  File "/Users/rr/Desktop/code/LearnBetter/venv/lib/python3.7/site-packages/sqlalchemy/util/compat.py", line 178, in raise_
    raise exception
  File "/Users/rr/Desktop/code/LearnBetter/venv/lib/python3.7/site-packages/sqlalchemy/engine/base.py", line 1284, in _execute_context
    cursor, statement, parameters, context
  File "/Users/rr/Desktop/code/LearnBetter/venv/lib/python3.7/site-packages/sqlalchemy/engine/default.py", line 590, in do_execute
    cursor.execute(statement, parameters)
sqlalchemy.exc.IntegrityError: (sqlite3.IntegrityError) UNIQUE constraint failed: user.username
[SQL: INSERT INTO user (goog_id, username, email, password_hash) VALUES (?, ?, ?, ?)]
[parameters: (None, 'alan', 'roznoshchik@gmail.com', 'pbkdf2:sha256:150000$jpcuMaGJ$e560c5a231bf2f0d86606d323e3650b5e4e36159a6cf6925c706e9808b770fa8')]
(Background on this error at: http://sqlalche.me/e/gkpj)
